Workbook
Name Slicer_City__Location: #N/A
Name Slicer_Industry_Vertical: #N/A
Name Slicer_Year1: #N/A

Sheet Total funding by IndustryVertic
A3: Row Labels | B3: Sum of Amount in USD
A4: Ecommerce | B4: 7163710608
A5: Consumer Internet | B5: 6245504245
A6: Transportation | B6: 3916632394
A7: Technology | B7: 2228607930
A8: Finance | B8: 1960938000
A9: nan | B9: 1230961368
A10: FinTech | B10: 1224211265
A11: E-commerce | B11: 1077793109
A12: Online Marketplace | B12: 700143000
A13: E-Commerce & M-Commerce platform | B13: 680000000
A14: B2B | B14: 587000000
A15: Car Aggregator & Retail Mobile App | B15: 500000000
... A797: Grand Total | B797: 37783048854

Sheet Top 10 Investors by amount
A3: Row Labels | B3: Sum of Amount in USD
A4: Westbridge Capital | B4: 3952000000
A5: Softbank | B5: 2500000000
A6: SoftBank Group | B6: 1467000000
A7: Microsoft, eBay, Tencent Holdings | B7: 1400000000
A8: Vijay Shekhar Sharma | B8: 1000150000
A9: Steadview Capital and existing investors | B9: 700000000
A10: Alibaba Group, Ant Financial | B10: 680000000
A11: N/A | B11: 615605951
A12: SoftBank Vision Fund | B12: 601000000
A13: Altimeter Capital, DST Global | B13: 585000000
A14: Baillie Gifford, Falcon Edge Capital, Tiger Global, SoftBank Group, DST Global, Didi Kuaidi | B14: 500000000
A15: Alibaba, Foxconn, Softbank | B15: 500000000
... A2375: Grand Total | B2375: 37783048854

Sheet Group Funding Amount
A3: Row Labels | B3: Sum of Amount in USD
A4: Bin1 | B4: 249922145
A5: Bin2 | B5: 3256168084
A6: Bin3 | B6: 34276958625
A7: Grand Total | B7: 37783048854

Sheet Funding by Year
A3: Row Labels | B3: Sum of Amount in USD
A4: 2015 | B4: 8556207368
A5: 2016 | B5: 3828058608
A6: 2017 | B6: 10429309730
A7: 2018 | B7: 5107818369
A8: 2019 | B8: 9471447525
A9: 2020 | B9: 390207254
A10: Grand Total | B10: 37783048854

Sheet Lookup 4
A3: Row Labels | B3: Sum of Amount in USD
A4: Angel | B4: 1752767523
A5: VC | B5: 8485526729
A6: Grand Total | B6: 10238294252

Sheet Average funding by industry
A3: Row Labels | B3: Average of Amount in USD
A4: Transportation | B4: 9.791581e+08
A5: E-Commerce & M-Commerce platform | B5: 680000000
A6: Ecommerce Marketplace | B6: 500000000
A7: Car Aggregator & Retail Mobile App | B7: 500000000
A8: Cab Aggregator | B8: 400000000
A9: Online Marketplace | B9: 350071500
A10: Automation | B10: 300000000
A11: B2B | B11: 293500000
A12: B2B Platform | B12: 225000000
A13: E-Tech | B13: 200000000
A14: Online Classifieds | B14: 150000000
A15: Last Mile Transportation | B15: 141650000
... A797: Grand Total | B797: 12542838

Sheet Total Funding
A3: Sum of Amount in USD
A4: 37854283854

Sheet Top Investor
A3: Row Labels | B3: Sum of Amount in USD
A4: Westbridge Capital | B4: 3952000000
A5: Grand Total | B5: 3952000000

Sheet Top City
A3: Row Labels | B3: Sum of Amount in USD
A4: Bangalore | B4: 8389991108
A5: Grand Total | B5: 8389991108

Sheet DashBoard
AL1: ="Indian Startup Funding Trends (" & TEXT(MIN(AC26:AC31), "0") & "–" & TEXT(MAX(AC26:AC31), "0") & ")" -> Indian Startup Funding Trends (2015–2020)
AC9: Sum of Amount in USD
AC10: 37854283854
AC12: Row Labels | AD12: Sum of Amount in USD
AC13: Westbridge Capital | AD13: 3952000000
AC14: Grand Total | AD14: 3952000000
AC17: Row Labels | AD17: Sum of Amount in USD
AC18: Bangalore | AD18: 8389991108
AC19: Grand Total | AD19: 8389991108
AC25: Year
AC26: 2015
AC27: 2016
AC28: 2017
AC29: 2018
AC30: 2019
AC31: 2020

Sheet Industry Share
A3: Row Labels | B3: Count of Industry Vertical
A4: Consumer Internet | B4: 938
A5: Technology | B5: 478
A6: Ecommerce | B6: 258
A7: nan | B7: 169
A8: Healthcare | B8: 71
A9: Finance | B9: 61
A10: E-commerce | B10: 40
A11: Logistics | B11: 32
A12: Education | B12: 23
A13: Food & Beverage | B13: 23
A14: Ed-Tech | B14: 15
A15: FinTech | B15: 10
... A797: Grand Total | B797: 3024

Sheet Funding Trend
A3: Row Labels | B3: Sum of Amount in USD
A4: 2017 | B4: 10429309730
A5: 2019 | B5: 9471447525
A6: 2015 | B6: 8627442368
A7: 2018 | B7: 5107818369
A8: 2016 | B8: 3828058608
A9: 2020 | B9: 390207254
A10: Grand Total | B10: 37854283854

Sheet Dynamic title
D2: ="Indian Startup Funding Trends (" & A4 & ")" -> Indian Startup Funding Trends (2015)
A3: Row Labels
A4: 2015
A5: 2016
A6: 2017
A7: 2018
A8: 2019
A9: 2020
A10: Grand Total

Sheet startup_funding
A1: Sr No | B1: Date dd/mm/yyyy | C1: Startup Name | D1: Industry Vertical | E1: SubVertical | F1: City Location | G1: Investors Name | H1: InvestmentnType | I1: Amount in USD | J1: Remarks | K1: Bins | L1: Year | M1: City(Xlookup) | N1: Investor Type | O1: Classification Investor Type | T1: Scroll Right to See table | W1: Investors Name | X1: InvestmentnType
A2: 1 | B2: 43839 | C2: BYJU’S | D2: E-Tech | E2: E-learning | F2: Bengaluru | G2: Tiger Global Management | H2: Private Equity Round | I2: 200000000 | K2: {=_xlfn.IFS(I2<1000000,"Bin1",AND(I2>=1000000,I2<=10000000),"Bin2",I2>10000000,"Bin3")} -> Bin3 | L2: =YEAR(B2) -> 2020 | M2: =_xlfn.XLOOKUP(C2,'LookUp Table'!$A$1:$A$3031,'LookUp Table'!$B$1:$B$3031,"Not Found",0) -> Bengaluru | N2: =IFERROR(VLOOKUP(G2,$W$1:$X$6025,2,FALSE),"Ignore") -> Private Equity Round | O2: =_xlfn.XLOOKUP(N2,'Com LookUp+Pivot'!$A$1:$A$49,'Com LookUp+Pivot'!$B$1:$B$49,"Not Found",0) -> PE | W2: Tiger Global Management | X2: Private Equity Round
A3: 2 | B3: 43843 | C3: Shuttl | D3: Transportation | E3: App based shuttle service | F3: Gurgaon | G3: Susquehanna Growth Equity | H3: Series C | I3: 8048394 | K3: {=_xlfn.IFS(I3<1000000,"Bin1",AND(I3>=1000000,I3<=10000000),"Bin2",I3>10000000,"Bin3")} -> Bin2 | L3: =YEAR(B3) -> 2020 | M3: =_xlfn.XLOOKUP(C3,'LookUp Table'!$A$1:$A$3031,'LookUp Table'!$B$1:$B$3031,"Not Found",0) -> Gurgaon | N3: =IFERROR(VLOOKUP(G3,$W$1:$X$6025,2,FALSE),"Ignore") -> Series C | O3: =_xlfn.XLOOKUP(N3,'Com LookUp+Pivot'!$A$1:$A$49,'Com LookUp+Pivot'!$B$1:$B$49,"Not Found",0) -> VC | W3: Susquehanna Growth Equity | X3: Series C
A4: 3 | B4: 43839 | C4: Mamaearth | D4: E-commerce | E4: Retailer of baby and toddler products | F4: Bengaluru | G4: Sequoia Capital India | H4: Series B | I4: 18358860 | K4: {=_xlfn.IFS(I4<1000000,"Bin1",AND(I4>=1000000,I4<=10000000),"Bin2",I4>10000000,"Bin3")} -> Bin3 | L4: =YEAR(B4) -> 2020 | M4: =_xlfn.XLOOKUP(C4,'LookUp Table'!$A$1:$A$3031,'LookUp Table'!$B$1:$B$3031,"Not Found",0) -> Bengaluru | N4: =IFERROR(VLOOKUP(G4,$W$1:$X$6025,2,FALSE),"Ignore") -> Series B | O4: =_xlfn.XLOOKUP(N4,'Com LookUp+Pivot'!$A$1:$A$49,'Com LookUp+Pivot'!$B$1:$B$49,"Not Found",0) -> VC | W4: Sequoia Capital India | X4: Series B
A5: 4 | B5: 43832 | C5: https://www.wealthbucket.in/ | D5: FinTech | E5: Online Investment | F5: New Delhi | G5: Vinod Khatumal | H5: Pre-series A | I5: 3000000 | K5: {=_xlfn.IFS(I5<1000000,"Bin1",AND(I5>=1000000,I5<=10000000),"Bin2",I5>10000000,"Bin3")} -> Bin2 | L5: =YEAR(B5) -> 2020 | M5: =_xlfn.XLOOKUP(C5,'LookUp Table'!$A$1:$A$3031,'LookUp Table'!$B$1:$B$3031,"Not Found",0) -> New Delhi | N5: =IFERROR(VLOOKUP(G5,$W$1:$X$6025,2,FALSE),"Ignore") -> Pre-series A | O5: =_xlfn.XLOOKUP(N5,'Com LookUp+Pivot'!$A$1:$A$49,'Com LookUp+Pivot'!$B$1:$B$49,"Not Found",0) -> VC | W5: Vinod Khatumal | X5: Pre-series A
A6: 5 | B6: 43832 | C6: Fashor | D6: Fashion and Apparel | E6: Embroiled Clothes For Women | F6: Mumbai | G6: Sprout Venture Partners | H6: Seed Round | I6: 1800000 | K6: {=_xlfn.IFS(I6<1000000,"Bin1",AND(I6>=1000000,I6<=10000000),"Bin2",I6>10000000,"Bin3")} -> Bin2 | L6: =YEAR(B6) -> 2020 | M6: =_xlfn.XLOOKUP(C6,'LookUp Table'!$A$1:$A$3031,'LookUp Table'!$B$1:$B$3031,"Not Found",0) -> Mumbai | N6: =IFERROR(VLOOKUP(G6,$W$1:$X$6025,2,FALSE),"Ignore") -> Seed Round | O6: =_xlfn.XLOOKUP(N6,'Com LookUp+Pivot'!$A$1:$A$49,'Com LookUp+Pivot'!$B$1:$B$49,"Not Found",0) -> Angel | W6: Sprout Venture Partners | X6: Seed Round
A7: 6 | B7: 43843 | C7: Pando | D7: Logistics | E7: Open-market, freight management platform | F7: Chennai | G7: Chiratae Ventures | H7: Series A | I7: 9000000 | K7: {=_xlfn.IFS(I7<1000000,"Bin1",AND(I7>=1000000,I7<=10000000),"Bin2",I7>10000000,"Bin3")} -> Bin2 | L7: =YEAR(B7) -> 2020 | M7: =_xlfn.XLOOKUP(C7,'LookUp Table'!$A$1:$A$3031,'LookUp Table'!$B$1:$B$3031,"Not Found",0) -> Chennai | N7: =IFERROR(VLOOKUP(G7,$W$1:$X$6025,2,FALSE),"Ignore") -> Series A | O7: =_xlfn.XLOOKUP(N7,'Com LookUp+Pivot'!$A$1:$A$49,'Com LookUp+Pivot'!$B$1:$B$49,"Not Found",0) -> VC | W7: Chiratae Ventures | X7: Series A
A8: 7 | B8: 43840 | C8: Zomato | D8: Hospitality | E8: Online Food Delivery Platform | F8: Gurgaon | G8: Ant Financial | H8: Private Equity Round | I8: 150000000 | K8: {=_xlfn.IFS(I8<1000000,"Bin1",AND(I8>=1000000,I8<=10000000),"Bin2",I8>10000000,"Bin3")} -> Bin3 | L8: =YEAR(B8) -> 2020 | M8: =_xlfn.XLOOKUP(C8,'LookUp Table'!$A$1:$A$3031,'LookUp Table'!$B$1:$B$3031,"Not Found",0) -> Gurgaon | N8: =IFERROR(VLOOKUP(G8,$W$1:$X$6025,2,FALSE),"Ignore") -> Private Equity Round | O8: =_xlfn.XLOOKUP(N8,'Com LookUp+Pivot'!$A$1:$A$49,'Com LookUp+Pivot'!$B$1:$B$49,"Not Found",0) -> PE | W8: Ant Financial | X8: Private Equity Round
A9: 8 | B9: 43811 | C9: Ecozen | D9: Technology | E9: Agritech | F9: Pune | G9: Sathguru Catalyzer Advisors | H9: Series A | I9: 6000000 | K9: {=_xlfn.IFS(I9<1000000,"Bin1",AND(I9>=1000000,I9<=10000000),"Bin2",I9>10000000,"Bin3")} -> Bin2 | L9: =YEAR(B9) -> 2019 | M9: =_xlfn.XLOOKUP(C9,'LookUp Table'!$A$1:$A$3031,'LookUp Table'!$B$1:$B$3031,"Not Found",0) -> Pune | N9: =IFERROR(VLOOKUP(G9,$W$1:$X$6025,2,FALSE),"Ignore") -> Series A | O9: =_xlfn.XLOOKUP(N9,'Com LookUp+Pivot'!$A$1:$A$49,'Com LookUp+Pivot'!$B$1:$B$49,"Not Found",0) -> VC | W9: Sathguru Catalyzer Advisors | X9: Series A
A10: 9 | B10: 43805 | C10: CarDekho | D10: E-Commerce | E10: Automobile | F10: Gurgaon | G10: Ping An Global Voyager Fund | H10: Series D | I10: 70000000 | K10: {=_xlfn.IFS(I10<1000000,"Bin1",AND(I10>=1000000,I10<=10000000),"Bin2",I10>10000000,"Bin3")} -> Bin3 | L10: =YEAR(B10) -> 2019 | M10: =_xlfn.XLOOKUP(C10,'LookUp Table'!$A$1:$A$3031,'LookUp Table'!$B$1:$B$3031,"Not Found",0) -> Gurgaon | N10: =IFERROR(VLOOKUP(G10,$W$1:$X$6025,2,FALSE),"Ignore") -> Series D | O10: =_xlfn.XLOOKUP(N10,'Com LookUp+Pivot'!$A$1:$A$49,'Com LookUp+Pivot'!$B$1:$B$49,"Not Found",0) -> VC | W10: Ping An Global Voyager Fund | X10: Series D
A11: 10 | B11: 43802 | C11: Dhruva Space | D11: Aerospace | E11: Satellite Communication | F11: Bengaluru | G11: Mumbai Angels, Ravikanth Reddy | H11: Seed | I11: 50000000 | K11: {=_xlfn.IFS(I11<1000000,"Bin1",AND(I11>=1000000,I11<=10000000),"Bin2",I11>10000000,"Bin3")} -> Bin3 | L11: =YEAR(B11) -> 2019 | M11: =_xlfn.XLOOKUP(C11,'LookUp Table'!$A$1:$A$3031,'LookUp Table'!$B$1:$B$3031,"Not Found",0) -> Bengaluru | N11: =IFERROR(VLOOKUP(G11,$W$1:$X$6025,2,FALSE),"Ignore") -> Seed | O11: =_xlfn.XLOOKUP(N11,'Com LookUp+Pivot'!$A$1:$A$49,'Com LookUp+Pivot'!$B$1:$B$49,"Not Found",0) -> Angel | W11: Mumbai Angels, Ravikanth Reddy | X11: Seed
A12: 11 | B12: 43812 | C12: Rivigo | D12: Technology | E12: Logistics Services and Solutions | F12: Gurgaon | G12: SAIF Partners, Spring Canter Investment Ltd. | H12: Series F | I12: 20000000 | K12: {=_xlfn.IFS(I12<1000000,"Bin1",AND(I12>=1000000,I12<=10000000),"Bin2",I12>10000000,"Bin3")} -> Bin3 | L12: =YEAR(B12) -> 2019 | M12: =_xlfn.XLOOKUP(C12,'LookUp Table'!$A$1:$A$3031,'LookUp Table'!$B$1:$B$3031,"Not Found",0) -> Gurgaon | N12: =IFERROR(VLOOKUP(G12,$W$1:$X$6025,2,FALSE),"Ignore") -> Series F | O12: =_xlfn.XLOOKUP(N12,'Com LookUp+Pivot'!$A$1:$A$49,'Com LookUp+Pivot'!$B$1:$B$49,"Not Found",0) -> VC | W12: SAIF Partners, Spring Canter Investment Ltd. | X12: Series F
A13: 12 | B13: 43816 | C13: Healthians | D13: B2B-focused foodtech startup | E13: Food Solutions For Corporate | F13: Bengaluru | G13: Paytm, NPTK, Sabre Partners and Neoplux | H13: Series C | I13: 12000000 | K13: {=_xlfn.IFS(I13<1000000,"Bin1",AND(I13>=1000000,I13<=10000000),"Bin2",I13>10000000,"Bin3")} -> Bin3 | L13: =YEAR(B13) -> 2019 | M13: =_xlfn.XLOOKUP(C13,'LookUp Table'!$A$1:$A$3031,'LookUp Table'!$B$1:$B$3031,"Not Found",0) -> Bengaluru | N13: =IFERROR(VLOOKUP(G13,$W$1:$X$6025,2,FALSE),"Ignore") -> Series C | O13: =_xlfn.XLOOKUP(N13,'Com LookUp+Pivot'!$A$1:$A$49,'Com LookUp+Pivot'!$B$1:$B$49,"Not Found",0) -> VC | W13: Paytm, NPTK, Sabre Partners and Neoplux | X13: Series C
... A43: 44 | B43: 43711 | C43: Vyapar App | D43: Accounting | E43: Mobile-based Accounting Software | F43: Bengaluru | G43: India Quotient, Axilor Ventures | H43: Series A | I43: 5000000 | K43: {=_xlfn.IFS(I43<1000000,"Bin1",AND(I43>=1000000,I43<=10000000),"Bin2",I43>10000000,"Bin3")} -> Bin2 | L43: =YEAR(B43) -> 2019 | M43: =_xlfn.XLOOKUP(C43,'LookUp Table'!$A$1:$A$3031,'LookUp Table'!$B$1:$B$3031,"Not Found",0) -> Bengaluru | N43: =IFERROR(VLOOKUP(G43,$W$1:$X$6025,2,FALSE),"Ignore") -> Series A | O43: =_xlfn.XLOOKUP(N43,'Com LookUp+Pivot'!$A$1:$A$49,'Com LookUp+Pivot'!$B$1:$B$49,"Not Found",0) -> VC | W43: India Quotient, Axilor Ventures | X43: Series A
A44: 45 | B44: 43678 | C44: CarDekho | D44: E-Commerce | E44: Automotive | F44: Gurgaon | G44: SC GG India Mobility Holdings LLC | H44: Series C | I44: 20000000 | J44: nan | K44: {=_xlfn.IFS(I44<1000000,"Bin1",AND(I44>=1000000,I44<=10000000),"Bin2",I44>10000000,"Bin3")} -> Bin3 | L44: =YEAR(B44) -> 2019 | M44: =_xlfn.XLOOKUP(C44,'LookUp Table'!$A$1:$A$3031,'LookUp Table'!$B$1:$B$3031,"Not Found",0) -> Gurgaon | N44: =IFERROR(VLOOKUP(G44,$W$1:$X$6025,2,FALSE),"Ignore") -> Series C | O44: =_xlfn.XLOOKUP(N44,'Com LookUp+Pivot'!$A$1:$A$49,'Com LookUp+Pivot'!$B$1:$B$49,"Not Found",0) -> VC | W44: SC GG India Mobility Holdings LLC | X44: Series C
A45: 46 | B45: 43678 | C45: Progcap | D45: Finance | E45: Supply Chain Management | F45: New Delhi | G45: Sequoia India | H45: Series A | I45: 5000000 | J45: nan | K45: {=_xlfn.IFS(I45<1000000,"Bin1",AND(I45>=1000000,I45<=10000000),"Bin2",I45>10000000,"Bin3")} -> Bin2 | L45: =YEAR(B45) -> 2019 | M45: =_xlfn.XLOOKUP(C45,'LookUp Table'!$A$1:$A$3031,'LookUp Table'!$B$1:$B$3031,"Not Found",0) -> New Delhi | N45: =IFERROR(VLOOKUP(G45,$W$1:$X$6025,2,FALSE),"Ignore") -> Series A | O45: =_xlfn.XLOOKUP(N45,'Com LookUp+Pivot'!$A$1:$A$49,'Com LookUp+Pivot'!$B$1:$B$49,"Not Found",0) -> VC | W45: Sequoia India | X45: Series A
A46: 48 | B46: 43678 | C46: Alteria Capital | D46: Finance | E46: VC Funds | F46: Mumbai | G46: Azim Premji, Binny Bansal | H46: Single Venture | I46: 140000000 | J46: nan | K46: {=_xlfn.IFS(I46<1000000,"Bin1",AND(I46>=1000000,I46<=10000000),"Bin2",I46>10000000,"Bin3")} -> Bin3 | L46: =YEAR(B46) -> 2019 | M46: =_xlfn.XLOOKUP(C46,'LookUp Table'!$A$1:$A$3031,'LookUp Table'!$B$1:$B$3031,"Not Found",0) -> Mumbai | N46: =IFERROR(VLOOKUP(G46,$W$1:$X$6025,2,FALSE),"Ignore") -> Single Venture | O46: =_xlfn.XLOOKUP(N46,'Com LookUp+Pivot'!$A$1:$A$49,'Com LookUp+Pivot'!$B$1:$B$49,"Not Found",0) -> Other | W46: Azim Premji, Binny Bansal | X46: Single Venture
A47: 49 | B47: 43678 | C47: Pine Labs | D47: Information Technology | E47: Last-mile retail transaction technology | F47: Noida | G47: Pine Labs Pte Ltd | H47: Corporate Round | I47: 38080000 | J47: nan | K47: {=_xlfn.IFS(I47<1000000,"Bin1",AND(I47>=1000000,I47<=10000000),"Bin2",I47>10000000,"Bin3")} -> Bin3 | L47: =YEAR(B47) -> 2019 | M47: =_xlfn.XLOOKUP(C47,'LookUp Table'!$A$1:$A$3031,'LookUp Table'!$B$1:$B$3031,"Not Found",0) -> Noida | N47: =IFERROR(VLOOKUP(G47,$W$1:$X$6025,2,FALSE),"Ignore") -> Corporate Round | O47: =_xlfn.XLOOKUP(N47,'Com LookUp+Pivot'!$A$1:$A$49,'Com LookUp+Pivot'!$B$1:$B$49,"Not Found",0) -> Other | W47: Pine Labs Pte Ltd | X47: Corporate Round
A48: 50 | B48: 43689 | C48: Meesho | D48: E-Commerce | E48: Social Commerce | F48: Bengaluru | G48: Naspers | H48: Series D | I48: 125000000 | J48: nan | K48: {=_xlfn.IFS(I48<1000000,"Bin1",AND(I48>=1000000,I48<=10000000),"Bin2",I48>10000000,"Bin3")} -> Bin3 | L48: =YEAR(B48) -> 2019 | M48: =_xlfn.XLOOKUP(C48,'LookUp Table'!$A$1:$A$3031,'LookUp Table'!$B$1:$B$3031,"Not Found",0) -> Bengaluru | N48: =IFERROR(VLOOKUP(G48,$W$1:$X$6025,2,FALSE),"Ignore") -> Series D | O48: =_xlfn.XLOOKUP(N48,'Com LookUp+Pivot'!$A$1:$A$49,'Com LookUp+Pivot'!$B$1:$B$49,"Not Found",0) -> VC | W48: Naspers | X48: Series D
A49: 51 | B49: 43690 | C49: Cars24 | D49: E-Commerce | E49: Car Retail | F49: Gurugram | G49: MS Dhoni | H49: Series D | I49: 11000000 | J49: nan | K49: {=_xlfn.IFS(I49<1000000,"Bin1",AND(I49>=1000000,I49<=10000000),"Bin2",I49>10000000,"Bin3")} -> Bin3 | L49: =YEAR(B49) -> 2019 | M49: =_xlfn.XLOOKUP(C49,'LookUp Table'!$A$1:$A$3031,'LookUp Table'!$B$1:$B$3031,"Not Found",0) -> Gurugram | N49: =IFERROR(VLOOKUP(G49,$W$1:$X$6025,2,FALSE),"Ignore") -> Series D | O49: =_xlfn.XLOOKUP(N49,'Com LookUp+Pivot'!$A$1:$A$49,'Com LookUp+Pivot'!$B$1:$B$49,"Not Found",0) -> VC | W49: MS Dhoni | X49: Series D
A50: 52 | B50: 43690 | C50: Uniphore | D50: Customer Service Platform | E50: Conversational AI | F50: Palo Alto | G50: March Capital Partners | H50: Series C | I50: 51000000 | J50: nan | K50: {=_xlfn.IFS(I50<1000000,"Bin1",AND(I50>=1000000,I50<=10000000),"Bin2",I50>10000000,"Bin3")} -> Bin3 | L50: =YEAR(B50) -> 2019 | M50: =_xlfn.XLOOKUP(C50,'LookUp Table'!$A$1:$A$3031,'LookUp Table'!$B$1:$B$3031,"Not Found",0) -> Palo Alto | N50: =IFERROR(VLOOKUP(G50,$W$1:$X$6025,2,FALSE),"Ignore") -> Series C | O50: =_xlfn.XLOOKUP(N50,'Com LookUp+Pivot'!$A$1:$A$49,'Com LookUp+Pivot'!$B$1:$B$49,"Not Found",0) -> VC | W50: March Capital Partners | X50: Series C
A51: 53 | B51: 43700 | C51: Zendrive | D51: Automotive | E51: Road Safety Analytics | F51: San Francisco | G51: XL Innovate | H51: Series B | I51: 37000000 | J51: nan | K51: {=_xlfn.IFS(I51<1000000,"Bin1",AND(I51>=1000000,I51<=10000000),"Bin2",I51>10000000,"Bin3")} -> Bin3 | L51: =YEAR(B51) -> 2019 | M51: =_xlfn.XLOOKUP(C51,'LookUp Table'!$A$1:$A$3031,'LookUp Table'!$B$1:$B$3031,"Not Found",0) -> San Francisco | N51: =IFERROR(VLOOKUP(G51,$W$1:$X$6025,2,FALSE),"Ignore") -> Series B | O51: =_xlfn.XLOOKUP(N51,'Com LookUp+Pivot'!$A$1:$A$49,'Com LookUp+Pivot'!$B$1:$B$49,"Not Found",0) -> VC | W51: XL Innovate | X51: Series B
A52: 54 | B52: 43700 | C52: Lo! Foods | D52: Consumer Goods | E52: Low carb food for Diabetics | F52: Bengaluru | G52: Rashmi Daga (founder, FreshMenu), Raveen Sastry (co-founder, Myntra) and Mitesh Shah (finance chief, BookMyShow) | H52: Seed Round | I52: 500000 | J52: nan | K52: {=_xlfn.IFS(I52<1000000,"Bin1",AND(I52>=1000000,I52<=10000000),"Bin2",I52>10000000,"Bin3")} -> Bin1 | L52: =YEAR(B52) -> 2019 | M52: =_xlfn.XLOOKUP(C52,'LookUp Table'!$A$1:$A$3031,'LookUp Table'!$B$1:$B$3031,"Not Found",0) -> Bengaluru | N52: =IFERROR(VLOOKUP(G52,$W$1:$X$6025,2,FALSE),"Ignore") -> Seed Round | O52: =_xlfn.XLOOKUP(N52,'Com LookUp+Pivot'!$A$1:$A$49,'Com LookUp+Pivot'!$B$1:$B$49,"Not Found",0) -> Angel | W52: Rashmi Daga (founder, FreshMenu), Raveen Sastry (co-founder, Myntra) and Mitesh Shah (finance chief, BookMyShow) | X52: Seed Round
A53: 55 | B53: 43700 | C53: Tala | D53: FinTech | E53: Digital Lending Platform | F53: Santa Monica | G53: RPS Ventures | H53: Series D | I53: 110000000 | J53: nan | K53: {=_xlfn.IFS(I53<1000000,"Bin1",AND(I53>=1000000,I53<=10000000),"Bin2",I53>10000000,"Bin3")} -> Bin3 | L53: =YEAR(B53) -> 2019 | M53: =_xlfn.XLOOKUP(C53,'LookUp Table'!$A$1:$A$3031,'LookUp Table'!$B$1:$B$3031,"Not Found",0) -> Santa Monica | N53: =IFERROR(VLOOKUP(G53,$W$1:$X$6025,2,FALSE),"Ignore") -> Series D | O53: =_xlfn.XLOOKUP(N53,'Com LookUp+Pivot'!$A$1:$A$49,'Com LookUp+Pivot'!$B$1:$B$49,"Not Found",0) -> VC | W53: RPS Ventures | X53: Series D
A54: 56 | B54: 43699 | C54: INDwealth | D54: FinTech | E54: Wealth Management | F54: Gurgaon | G54: Tiger Global Management | H54: Venture Round | I54: 15000000 | J54: nan | K54: {=_xlfn.IFS(I54<1000000,"Bin1",AND(I54>=1000000,I54<=10000000),"Bin2",I54>10000000,"Bin3")} -> Bin3 | L54: =YEAR(B54) -> 2019 | M54: =_xlfn.XLOOKUP(C54,'LookUp Table'!$A$1:$A$3031,'LookUp Table'!$B$1:$B$3031,"Not Found",0) -> Gurgaon | N54: =IFERROR(VLOOKUP(G54,$W$1:$X$6025,2,FALSE),"Ignore") -> Private Equity Round | O54: =_xlfn.XLOOKUP(N54,'Com LookUp+Pivot'!$A$1:$A$49,'Com LookUp+Pivot'!$B$1:$B$49,"Not Found",0) -> PE | W54: Tiger Global Management | X54: Venture Round
A55: 57 | B55: 43698 | C55: HungerBox | D55: Food and Beverage | E55: B2B Foodtech | F55: Bengaluru | G55: One97 Communications Ltd. | H55: Series C | I55: 6590000 | J55: nan | K55: {=_xlfn.IFS(I55<1000000,"Bin1",AND(I55>=1000000,I55<=10000000),"Bin2",I55>10000000,"Bin3")} -> Bin2 | L55: =YEAR(B55) -> 2019 | M55: =_xlfn.XLOOKUP(C55,'LookUp Table'!$A$1:$A$3031,'LookUp Table'!$B$1:$B$3031,"Not Found",0) -> Bengaluru | N55: =IFERROR(VLOOKUP(G55,$W$1:$X$6025,2,FALSE),"Ignore") -> Series C | O55: =_xlfn.XLOOKUP(N55,'Com LookUp+Pivot'!$A$1:$A$49,'Com LookUp+Pivot'!$B$1:$B$49,"Not Found",0) -> VC | W55: One97 Communications Ltd. | X55: Series C
... A105: 109 | B105: 43574 | C105: My Healthcare | D105: E-commerce | E105: Software Solutions | F105: Bengaluru and Gurugram | G105: Sixth Sense Ventures | H105: Series A | I105: 3000000 | J105: nan | K105: {=_xlfn.IFS(I105<1000000,"Bin1",AND(I105>=1000000,I105<=10000000),"Bin2",I105>10000000,"Bin3")} -> Bin2 | L105: =YEAR(B105) -> 2019 | M105: =_xlfn.XLOOKUP(C105,'LookUp Table'!$A$1:$A$3031,'LookUp Table'!$B$1:$B$3031,"Not Found",0) -> Bengaluru and Gurugram | N105: =IFERROR(VLOOKUP(G105,$W$1:$X$6025,2,FALSE),"Ignore") -> Series B | O105: =_xlfn.XLOOKUP(N105,'Com LookUp+Pivot'!$A$1:$A$49,'Com LookUp+Pivot'!$B$1:$B$49,"Not Found",0) -> VC | W105: Sixth Sense Ventures | X105: Series A
A106: 110 | B106: 43574 | C106: KrazyBee | D106: E-commerce | E106: Lending Platform | F106: Bengaluru | G106: BAC Acquisitions, Unifi AIF, BRD Securities, Northern R Capital | H106: Debt | I106: 14,342,000+ | J106: nan | K106: {=_xlfn.IFS(I106<1000000,"Bin1",AND(I106>=1000000,I106<=10000000),"Bin2",I106>10000000,"Bin3")} -> Bin3 | L106: =YEAR(B106) -> 2019 | M106: =_xlfn.XLOOKUP(C106,'LookUp Table'!$A$1:$A$3031,'LookUp Table'!$B$1:$B$3031,"Not Found",0) -> Bengaluru | N106: =IFERROR(VLOOKUP(G106,$W$1:$X$6025,2,FALSE),"Ignore") -> Debt | O106: =_xlfn.XLOOKUP(N106,'Com LookUp+Pivot'!$A$1:$A$49,'Com LookUp+Pivot'!$B$1:$B$49,"Not Found",0) -> Other | W106: BAC Acquisitions, Unifi AIF, BRD Securities, Northern R Capital | X106: Debt
A107: 111 | B107: 43572 | C107: Shuttl | D107: Transportation | E107: Bus Aggregation | F107: Gurugram | G107: New Atlantic Ventures | H107: Venture Round | I107: 5000000 | J107: nan | K107: {=_xlfn.IFS(I107<1000000,"Bin1",AND(I107>=1000000,I107<=10000000),"Bin2",I107>10000000,"Bin3")} -> Bin2 | L107: =YEAR(B107) -> 2019 | M107: =_xlfn.XLOOKUP(C107,'LookUp Table'!$A$1:$A$3031,'LookUp Table'!$B$1:$B$3031,"Not Found",0) -> Gurgaon | N107: =IFERROR(VLOOKUP(G107,$W$1:$X$6025,2,FALSE),"Ignore") -> Venture Round | O107: =_xlfn.XLOOKUP(N107,'Com LookUp+Pivot'!$A$1:$A$49,'Com LookUp+Pivot'!$B$1:$B$49,"Not Found",0) -> Other | W107: New Atlantic Ventures | X107: Venture Round
A108: 112 | B108: 43572 | C108: Increff | D108: Technology | E108: Supply-chain technology solutions | F108: Bengaluru | G108: 021 Capita, Binny Bansal | H108: Series A | I108: 3000000 | J108: nan | K108: {=_xlfn.IFS(I108<1000000,"Bin1",AND(I108>=1000000,I108<=10000000),"Bin2",I108>10000000,"Bin3")} -> Bin2 | L108: =YEAR(B108) -> 2019 | M108: =_xlfn.XLOOKUP(C108,'LookUp Table'!$A$1:$A$3031,'LookUp Table'!$B$1:$B$3031,"Not Found",0) -> Bengaluru | N108: =IFERROR(VLOOKUP(G108,$W$1:$X$6025,2,FALSE),"Ignore") -> Series A | O108: =_xlfn.XLOOKUP(N108,'Com LookUp+Pivot'!$A$1:$A$49,'Com LookUp+Pivot'!$B$1:$B$49,"Not Found",0) -> VC | W108: 021 Capita, Binny Bansal | X108: Series A
A109: 113 | B109: 43497 | C109: FleetX | D109: AI | E109: Logistics | F109: Gurgaon | G109: India Quotient and LetsVenture\\xe2\\x80\\x99s Angel Fund | H109: Pre Series A | I109: 0 | J109: nan | K109: {=_xlfn.IFS(I109<1000000,"Bin1",AND(I109>=1000000,I109<=10000000),"Bin2",I109>10000000,"Bin3")} -> Bin1 | L109: =YEAR(B109) -> 2019 | M109: =_xlfn.XLOOKUP(C109,'LookUp Table'!$A$1:$A$3031,'LookUp Table'!$B$1:$B$3031,"Not Found",0) -> Gurgaon | N109: =IFERROR(VLOOKUP(G109,$W$1:$X$6025,2,FALSE),"Ignore") -> Pre Series A | O109: =_xlfn.XLOOKUP(N109,'Com LookUp+Pivot'!$A$1:$A$49,'Com LookUp+Pivot'!$B$1:$B$49,"Not Found",0) -> VC | W109: India Quotient and LetsVenture\\xe2\\x80\\x99s Angel Fund | X109: Pre Series A
A110: 114 | B110: 43504 | C110: Zilingo | D110: Ecommerce | E110: Fashion & Apparel | F110: India/Singapore | G110: Sequoia Capital and Temasek Holdings, EDBI, Burda Principal Investments, and Sofina | H110: Series D | I110: 226000000 | J110: nan | K110: {=_xlfn.IFS(I110<1000000,"Bin1",AND(I110>=1000000,I110<=10000000),"Bin2",I110>10000000,"Bin3")} -> Bin3 | L110: =YEAR(B110) -> 2019 | M110: =_xlfn.XLOOKUP(C110,'LookUp Table'!$A$1:$A$3031,'LookUp Table'!$B$1:$B$3031,"Not Found",0) -> India/Singapore | N110: =IFERROR(VLOOKUP(G110,$W$1:$X$6025,2,FALSE),"Ignore") -> Series D | O110: =_xlfn.XLOOKUP(N110,'Com LookUp+Pivot'!$A$1:$A$49,'Com LookUp+Pivot'!$B$1:$B$49,"Not Found",0) -> VC | W110: Sequoia Capital and Temasek Holdings, EDBI, Burda Principal Investments, and Sofina | X110: Series D
A111: 115 | B111: 43509 | C111: NanoClean Global | D111: Nanotechnology | E111: Anti-Pollution | F111: New Delhi | G111: LetsVenture, PitchRight Venture, 91SpringBoard, AL Nour International Holdings and Mark V Investments | H111: Series A | I111: 600000 | J111: nan | K111: {=_xlfn.IFS(I111<1000000,"Bin1",AND(I111>=1000000,I111<=10000000),"Bin2",I111>10000000,"Bin3")} -> Bin1 | L111: =YEAR(B111) -> 2019 | M111: =_xlfn.XLOOKUP(C111,'LookUp Table'!$A$1:$A$3031,'LookUp Table'!$B$1:$B$3031,"Not Found",0) -> New Delhi | N111: =IFERROR(VLOOKUP(G111,$W$1:$X$6025,2,FALSE),"Ignore") -> Series A | O111: =_xlfn.XLOOKUP(N111,'Com LookUp+Pivot'!$A$1:$A$49,'Com LookUp+Pivot'!$B$1:$B$49,"Not Found",0) -> VC | W111: LetsVenture, PitchRight Venture, 91SpringBoard, AL Nour International Holdings and Mark V Investments | X111: Series A
A112: 116 | B112: 43145 | C112: OyoRooms | D112: Hospitality | E112: Budget Rooms | F112: Gurgaon | G112: DiDi Chuxing | H112: Equity | I112: 100000000 | J112: nan | K112: {=_xlfn.IFS(I112<1000000,"Bin1",AND(I112>=1000000,I112<=10000000),"Bin2",I112>10000000,"Bin3")} -> Bin3 | L112: =YEAR(B112) -> 2018 | M112: =_xlfn.XLOOKUP(C112,'LookUp Table'!$A$1:$A$3031,'LookUp Table'!$B$1:$B$3031,"Not Found",0) -> Gurgaon | N112: =IFERROR(VLOOKUP(G112,$W$1:$X$6025,2,FALSE),"Ignore") -> Equity | O112: =_xlfn.XLOOKUP(N112,'Com LookUp+Pivot'!$A$1:$A$49,'Com LookUp+Pivot'!$B$1:$B$49,"Not Found",0) -> PE | W112: DiDi Chuxing | X112: Equity
A113: 117 | B113: 43468 | C113: CarDekho | D113: Automobile | E113: Online Marketplace | F113: Jaipur | G113: Sequoia India, Hillhouse Capital, Alphabet\\xe2\\x80\\x99s growth investment arm Capital G and Axis Bank | H113: Series C | I113: 110000000 | J113: nan | K113: {=_xlfn.IFS(I113<1000000,"Bin1",AND(I113>=1000000,I113<=10000000),"Bin2",I113>10000000,"Bin3")} -> Bin3 | L113: =YEAR(B113) -> 2019 | M113: =_xlfn.XLOOKUP(C113,'LookUp Table'!$A$1:$A$3031,'LookUp Table'!$B$1:$B$3031,"Not Found",0) -> Gurgaon | N113: =IFERROR(VLOOKUP(G113,$W$1:$X$6025,2,FALSE),"Ignore") -> Series C | O113: =_xlfn.XLOOKUP(N113,'Com LookUp+Pivot'!$A$1:$A$49,'Com LookUp+Pivot'!$B$1:$B$49,"Not Found",0) -> VC | W113: Sequoia India, Hillhouse Capital, Alphabet\\xe2\\x80\\x99s growth investment arm Capital G and Axis Bank | X113: Series C
A114: 118 | B114: 43469 | C114: Vyome Therapeutics Inc. | D114: Health and Wellness | E114: Specialty pharmaceutical | F114: India/US | G114: Iron Pillar, Perceptive Advisors, Romulus Capital and Kalaari Capital | H114: Series D | I114: 22000000 | J114: nan | K114: {=_xlfn.IFS(I114<1000000,"Bin1",AND(I114>=1000000,I114<=10000000),"Bin2",I114>10000000,"Bin3")} -> Bin3 | L114: =YEAR(B114) -> 2019 | M114: =_xlfn.XLOOKUP(C114,'LookUp Table'!$A$1:$A$3031,'LookUp Table'!$B$1:$B$3031,"Not Found",0) -> India/US | N114: =IFERROR(VLOOKUP(G114,$W$1:$X$6025,2,FALSE),"Ignore") -> Series D | O114: =_xlfn.XLOOKUP(N114,'Com LookUp+Pivot'!$A$1:$A$49,'Com LookUp+Pivot'!$B$1:$B$49,"Not Found",0) -> VC | W114: Iron Pillar, Perceptive Advisors, Romulus Capital and Kalaari Capital | X114: Series D
A115: 119 | B115: 43469 | C115: Samunnati Financial Intermediation & Services Pvt. Ltd | D115: Finance | E115: Non-banking financial company | F115: Chennai | G115: MASSIF, a Dutch government fund | H115: Debt-Funding | I115: 5000000 | J115: nan | K115: {=_xlfn.IFS(I115<1000000,"Bin1",AND(I115>=1000000,I115<=10000000),"Bin2",I115>10000000,"Bin3")} -> Bin2 | L115: =YEAR(B115) -> 2019 | M115: =_xlfn.XLOOKUP(C115,'LookUp Table'!$A$1:$A$3031,'LookUp Table'!$B$1:$B$3031,"Not Found",0) -> Chennai | N115: =IFERROR(VLOOKUP(G115,$W$1:$X$6025,2,FALSE),"Ignore") -> Debt-Funding | O115: =_xlfn.XLOOKUP(N115,'Com LookUp+Pivot'!$A$1:$A$49,'Com LookUp+Pivot'!$B$1:$B$49,"Not Found",0) -> Other | W115: MASSIF, a Dutch government fund | X115: Debt-Funding
A116: 120 | B116: 43438 | C116: Manch | D116: Social Media | E116: Hyperlocal Content | F116: Delhi | G116: Stellaris Venture Partners | H116: Seed Funding | I116: 700000 | J116: nan | K116: {=_xlfn.IFS(I116<1000000,"Bin1",AND(I116>=1000000,I116<=10000000),"Bin2",I116>10000000,"Bin3")} -> Bin1 | L116: =YEAR(B116) -> 2018 | M116: =_xlfn.XLOOKUP(C116,'LookUp Table'!$A$1:$A$3031,'LookUp Table'!$B$1:$B$3031,"Not Found",0) -> Delhi | N116: =IFERROR(VLOOKUP(G116,$W$1:$X$6025,2,FALSE),"Ignore") -> Seed Funding | O116: =_xlfn.XLOOKUP(N116,'Com LookUp+Pivot'!$A$1:$A$49,'Com LookUp+Pivot'!$B$1:$B$49,"Not Found",0) -> Angel | W116: Stellaris Venture Partners | X116: Seed Funding
A117: 121 | B117: 43435 | C117: UrbanClap Technologies Pvt. Ltd | D117: Services Platform | E117: Home services marketplace | F117: New Delhi | G117: Steadview Capital and Vy Capital. | H117: Series D | I117: 50000000 | J117: nan | K117: {=_xlfn.IFS(I117<1000000,"Bin1",AND(I117>=1000000,I117<=10000000),"Bin2",I117>10000000,"Bin3")} -> Bin3 | L117: =YEAR(B117) -> 2018 | M117: =_xlfn.XLOOKUP(C117,'LookUp Table'!$A$1:$A$3031,'LookUp Table'!$B$1:$B$3031,"Not Found",0) -> New Delhi | N117: =IFERROR(VLOOKUP(G117,$W$1:$X$6025,2,FALSE),"Ignore") -> Series D | O117: =_xlfn.XLOOKUP(N117,'Com LookUp+Pivot'!$A$1:$A$49,'Com LookUp+Pivot'!$B$1:$B$49,"Not Found",0) -> VC | W117: Steadview Capital and Vy Capital. | X117: Series D
A118: 122 | B118: 43436 | C118: Guiddoo | D118: Travel Tech | E118: Platform for travel agents | F118: Mumbai | G118: Individual Investors | H118: Pre-Series A | I118: 800000 | J118: nan | K118: {=_xlfn.IFS(I118<1000000,"Bin1",AND(I118>=1000000,I118<=10000000),"Bin2",I118>10000000,"Bin3")} -> Bin1 | L118: =YEAR(B118) -> 2018 | M118: =_xlfn.XLOOKUP(C118,'LookUp Table'!$A$1:$A$3031,'LookUp Table'!$B$1:$B$3031,"Not Found",0) -> Mumbai | N118: =IFERROR(VLOOKUP(G118,$W$1:$X$6025,2,FALSE),"Ignore") -> Pre-Series A | O118: =_xlfn.XLOOKUP(N118,'Com LookUp+Pivot'!$A$1:$A$49,'Com LookUp+Pivot'!$B$1:$B$49,"Not Found",0) -> VC | W118: Individual Investors | X118: Pre-Series A
...

Sheet LookUp Table
A1: Startup Name | B1: City Location
A2: BYJU’S | B2: Bengaluru
A3: Shuttl | B3: Gurgaon
A4: Mamaearth | B4: Bengaluru
A5: https://www.wealthbucket.in/ | B5: New Delhi
A6: Fashor | B6: Mumbai
A7: Pando | B7: Chennai
A8: Zomato | B8: Gurgaon
A9: Ecozen | B9: Pune
A10: CarDekho | B10: Gurgaon
A11: Dhruva Space | B11: Bengaluru
A12: Rivigo | B12: Gurgaon
... A3031: couponmachine.in | B3031: nan

Sheet Com LookUp+Pivot
A1: Investor Type | B1: Classification Investor Type
A2: Private Equity Round | B2: =IF(OR(ISNUMBER(SEARCH("seed",A2)),ISNUMBER(SEARCH("angel",A2))), "Angel", IF(OR(ISNUMBER(SEARCH("series",A2)),ISNUMBER(SEARCH("pre-series",A2))), "VC", IF(ISNUMBER(SEARCH("equity",A2)), "PE", "Other"))) -> PE
A3: Series C | B3: =IF(OR(ISNUMBER(SEARCH("seed",A3)),ISNUMBER(SEARCH("angel",A3))), "Angel", IF(OR(ISNUMBER(SEARCH("series",A3)),ISNUMBER(SEARCH("pre-series",A3))), "VC", IF(ISNUMBER(SEARCH("equity",A3)), "PE", "Other"))) -> VC
A4: Series B | B4: =IF(OR(ISNUMBER(SEARCH("seed",A4)),ISNUMBER(SEARCH("angel",A4))), "Angel", IF(OR(ISNUMBER(SEARCH("series",A4)),ISNUMBER(SEARCH("pre-series",A4))), "VC", IF(ISNUMBER(SEARCH("equity",A4)), "PE", "Other"))) -> VC
A5: Pre-series A | B5: =IF(OR(ISNUMBER(SEARCH("seed",A5)),ISNUMBER(SEARCH("angel",A5))), "Angel", IF(OR(ISNUMBER(SEARCH("series",A5)),ISNUMBER(SEARCH("pre-series",A5))), "VC", IF(ISNUMBER(SEARCH("equity",A5)), "PE", "Other"))) -> VC
A6: Seed Round | B6: =IF(OR(ISNUMBER(SEARCH("seed",A6)),ISNUMBER(SEARCH("angel",A6))), "Angel", IF(OR(ISNUMBER(SEARCH("series",A6)),ISNUMBER(SEARCH("pre-series",A6))), "VC", IF(ISNUMBER(SEARCH("equity",A6)), "PE", "Other"))) -> Angel
A7: Series A | B7: =IF(OR(ISNUMBER(SEARCH("seed",A7)),ISNUMBER(SEARCH("angel",A7))), "Angel", IF(OR(ISNUMBER(SEARCH("series",A7)),ISNUMBER(SEARCH("pre-series",A7))), "VC", IF(ISNUMBER(SEARCH("equity",A7)), "PE", "Other"))) -> VC
A8: Series D | B8: =IF(OR(ISNUMBER(SEARCH("seed",A8)),ISNUMBER(SEARCH("angel",A8))), "Angel", IF(OR(ISNUMBER(SEARCH("series",A8)),ISNUMBER(SEARCH("pre-series",A8))), "VC", IF(ISNUMBER(SEARCH("equity",A8)), "PE", "Other"))) -> VC
A9: Seed | B9: =IF(OR(ISNUMBER(SEARCH("seed",A9)),ISNUMBER(SEARCH("angel",A9))), "Angel", IF(OR(ISNUMBER(SEARCH("series",A9)),ISNUMBER(SEARCH("pre-series",A9))), "VC", IF(ISNUMBER(SEARCH("equity",A9)), "PE", "Other"))) -> Angel
A10: Series F | B10: =IF(OR(ISNUMBER(SEARCH("seed",A10)),ISNUMBER(SEARCH("angel",A10))), "Angel", IF(OR(ISNUMBER(SEARCH("series",A10)),ISNUMBER(SEARCH("pre-series",A10))), "VC", IF(ISNUMBER(SEARCH("equity",A10)), "PE", "Other"))) -> VC
A11: Series E | B11: =IF(OR(ISNUMBER(SEARCH("seed",A11)),ISNUMBER(SEARCH("angel",A11))), "Angel", IF(OR(ISNUMBER(SEARCH("series",A11)),ISNUMBER(SEARCH("pre-series",A11))), "VC", IF(ISNUMBER(SEARCH("equity",A11)), "PE", "Other"))) -> VC
A12: Series G | B12: =IF(OR(ISNUMBER(SEARCH("seed",A12)),ISNUMBER(SEARCH("angel",A12))), "Angel", IF(OR(ISNUMBER(SEARCH("series",A12)),ISNUMBER(SEARCH("pre-series",A12))), "VC", IF(ISNUMBER(SEARCH("equity",A12)), "PE", "Other"))) -> VC
A13: Series H | B13: =IF(OR(ISNUMBER(SEARCH("seed",A13)),ISNUMBER(SEARCH("angel",A13))), "Angel", IF(OR(ISNUMBER(SEARCH("series",A13)),ISNUMBER(SEARCH("pre-series",A13))), "VC", IF(ISNUMBER(SEARCH("equity",A13)), "PE", "Other"))) -> VC
... A49: Crowd funding | B49: =IF(OR(ISNUMBER(SEARCH("seed",A49)),ISNUMBER(SEARCH("angel",A49))), "Angel", IF(OR(ISNUMBER(SEARCH("series",A49)),ISNUMBER(SEARCH("pre-series",A49))), "VC", IF(ISNUMBER(SEARCH("equity",A49)), "PE", "Other"))) -> Other
